<mujoco model="TurboV1">

  <compiler meshdir="/Users/venky/Documents/Projects/DRL_TurboEngine/DRLTurboEngines/DRL_TurboEngine_V1/Tracks_STL/Track_V2"/>
  <compiler angle="degree" coordinate="local"/>
  <option timestep="0.01"/>

  <default>
    <joint armature="0.01" damping="1" limited="true"/>
  </default>

  <asset>

    <mesh name="L1" file="L1.stl" scale="0.2 0.05 0.2"/>
    <mesh name="R1" file="R1.stl" scale="0.2 0.05 0.2"/>
    <mesh name="R2" file="R2.stl" scale="0.2 0.05 0.2"/>
    <mesh name="L2" file="L2.stl" scale="0.2 0.05 0.2"/>
    <mesh name="R3" file="R3.stl" scale="0.2 0.05 0.2"/>
    <mesh name="L3" file="L3.stl" scale="0.2 0.05 0.2"/>
    <mesh name="R4" file="R4.stl" scale="0.2 0.05 0.2"/>
    <mesh name="L4" file="L4.stl" scale="0.2 0.05 0.2"/>
    <mesh name="R5" file="R5.stl" scale="0.2 0.05 0.2"/>
    <mesh name="L5" file="L5.stl" scale="0.2 0.05 0.2"/>
    <mesh name="R6" file="R6.stl" scale="0.2 0.05 0.2"/>
    <mesh name="L6" file="L6.stl" scale="0.2 0.05 0.2"/>
    <mesh name="R7" file="R7.stl" scale="0.2 0.05 0.2"/>
    <mesh name="L7" file="L7.stl" scale="0.2 0.05 0.2"/>
    <mesh name="R8" file="R8.stl" scale="0.2 0.05 0.2"/>
    <mesh name="L8" file="L8.stl" scale="0.2 0.05 0.2"/>
    <mesh name="R9" file="R9.stl" scale="0.2 0.05 0.2"/>
    <mesh name="L9" file="L9.stl" scale="0.2 0.05 0.2"/>
    <mesh name="R10" file="R10.stl" scale="0.2 0.05 0.2"/>
    <mesh name="L10" file="L10.stl" scale="0.2 0.05 0.2"/>
    <mesh name="R11" file="R11.stl" scale="0.2 0.05 0.2"/>
    <mesh name="L11" file="L11.stl" scale="0.2 0.05 0.2"/>
    <mesh name="R12" file="R12.stl" scale="0.2 0.05 0.2"/>
    <mesh name="L12" file="L12.stl" scale="0.2 0.05 0.2"/>
    <mesh name="R13" file="R13.stl" scale="0.2 0.05 0.2"/>
    <mesh name="L13" file="L13.stl" scale="0.2 0.05 0.2"/>
    <mesh name="R14" file="R14.stl" scale="0.2 0.05 0.2"/>
    <mesh name="L14" file="L14.stl" scale="0.2 0.05 0.2"/>
    <mesh name="R15" file="R15.stl" scale="0.2 0.05 0.2"/>
    <mesh name="L15" file="L15.stl" scale="0.2 0.05 0.2"/>
    <mesh name="R16" file="R16.stl" scale="0.2 0.05 0.2"/>
    <mesh name="L16" file="L16.stl" scale="0.2 0.05 0.2"/>
    <mesh name="R17" file="R17.stl" scale="0.2 0.05 0.2"/>
    <mesh name="L17" file="L17.stl" scale="0.2 0.05 0.2"/>
    <mesh name="R18" file="R18.stl" scale="0.2 0.05 0.2"/>
    <mesh name="L18" file="L18.stl" scale="0.2 0.05 0.2"/>
    <mesh name="R19" file="R19.stl" scale="0.2 0.05 0.2"/>
    <mesh name="L19" file="L19.stl" scale="0.2 0.05 0.2"/>
    <mesh name="R20" file="R20.stl" scale="0.2 0.05 0.2"/>
    <mesh name="L20" file="L20.stl" scale="0.2 0.05 0.2"/>
    <mesh name="R21" file="R21.stl" scale="0.2 0.05 0.2"/>
    <mesh name="L21" file="L21.stl" scale="0.2 0.05 0.2"/>
    <mesh name="R22" file="R22.stl" scale="0.2 0.05 0.2"/>
    <mesh name="L22" file="L22.stl" scale="0.2 0.05 0.2"/>


  </asset>

  <worldbody>
    <geom name="ground Plane" type="plane" pos="0 0 0" size="90 90 1" rgba="1 1 1 1"/> 
    <geom name="wall_boundary1" type="box" pos="90 0 5" size="0.5 90 5" rgba="0.7 0.7 0.7 1" contype="1" conaffinity="1"/>
    <geom name="wall_boundary2"  type="box" pos="-90 0 5" size="0.5 90 5" rgba="0.7 0.7 0.7 1" contype="1" conaffinity="1"/>
    <geom name="wall_boundary3"  type="box" pos="0 -90 5" size="90 0.5 5" rgba="0.7 0.7 0.7 1" contype="1" conaffinity="1"/>
    <geom name="wall_boundary4" type="box" pos="0 90 5" size="90 0.5 5" rgba="0.7 0.7 0.7 1" contype="1" conaffinity="1"/>

    <geom type="mesh" mesh="L1" xyaxes="1 0 0 0 0 1" pos="0 0 0"/>
    <geom type="mesh" mesh="R1" xyaxes="1 0 0 0 0 1" pos="0 0 0"/>
    <geom type="mesh" mesh="R2" xyaxes="1 0 0 0 0 1" pos="0 0 0"/>
    <geom type="mesh" mesh="L2" xyaxes="1 0 0 0 0 1" pos="0 0 0"/>
    <geom type="mesh" mesh="R3" xyaxes="1 0 0 0 0 1" pos="0 0 0"/>
    <geom type="mesh" mesh="L3" xyaxes="1 0 0 0 0 1" pos="0 0 0"/>
    <geom type="mesh" mesh="R4" xyaxes="1 0 0 0 0 1" pos="0 0 0"/>
    <geom type="mesh" mesh="L4" xyaxes="1 0 0 0 0 1" pos="0 0 0"/>
    <geom type="mesh" mesh="R5" xyaxes="1 0 0 0 0 1" pos="0 0 0"/>
    <geom type="mesh" mesh="L5" xyaxes="1 0 0 0 0 1" pos="0 0 0"/>
    <geom type="mesh" mesh="R6" xyaxes="1 0 0 0 0 1" pos="0 0 0"/>
    <geom type="mesh" mesh="L6" xyaxes="1 0 0 0 0 1" pos="0 0 0"/>
    <geom type="mesh" mesh="R7" xyaxes="1 0 0 0 0 1" pos="0 0 0"/>
    <geom type="mesh" mesh="L7" xyaxes="1 0 0 0 0 1" pos="0 0 0"/>
    <geom type="mesh" mesh="R8" xyaxes="1 0 0 0 0 1" pos="0 0 0"/>
    <geom type="mesh" mesh="L8" xyaxes="1 0 0 0 0 1" pos="0 0 0"/>
    <geom type="mesh" mesh="R9" xyaxes="1 0 0 0 0 1" pos="0 0 0"/>
    <geom type="mesh" mesh="L9" xyaxes="1 0 0 0 0 1" pos="0 0 0"/>
    <geom type="mesh" mesh="R10" xyaxes="1 0 0 0 0 1" pos="0 0 0"/>
    <geom type="mesh" mesh="L10" xyaxes="1 0 0 0 0 1" pos="0 0 0"/>
    <geom type="mesh" mesh="R11" xyaxes="1 0 0 0 0 1" pos="0 0 0"/>
    <geom type="mesh" mesh="L11" xyaxes="1 0 0 0 0 1" pos="0 0 0"/>
    <geom type="mesh" mesh="R12" xyaxes="1 0 0 0 0 1" pos="0 0 0"/>
    <geom type="mesh" mesh="L12" xyaxes="1 0 0 0 0 1" pos="0 0 0"/>
    <geom type="mesh" mesh="R13" xyaxes="1 0 0 0 0 1" pos="0 0 0"/>
    <geom type="mesh" mesh="L13" xyaxes="1 0 0 0 0 1" pos="0 0 0"/>
    <geom type="mesh" mesh="R14" xyaxes="1 0 0 0 0 1" pos="0 0 0"/>
    <geom type="mesh" mesh="L14" xyaxes="1 0 0 0 0 1" pos="0 0 0"/>
    <geom type="mesh" mesh="R15" xyaxes="1 0 0 0 0 1" pos="0 0 0"/>
    <geom type="mesh" mesh="L15" xyaxes="1 0 0 0 0 1" pos="0 0 0"/>
    <geom type="mesh" mesh="R16" xyaxes="1 0 0 0 0 1" pos="0 0 0"/>
    <geom type="mesh" mesh="L16" xyaxes="1 0 0 0 0 1" pos="0 0 0"/>
    <geom type="mesh" mesh="R17" xyaxes="1 0 0 0 0 1" pos="0 0 0"/>
    <geom type="mesh" mesh="L17" xyaxes="1 0 0 0 0 1" pos="0 0 0"/>
    <geom type="mesh" mesh="R18" xyaxes="1 0 0 0 0 1" pos="0 0 0"/>
    <geom type="mesh" mesh="L18" xyaxes="1 0 0 0 0 1" pos="0 0 0"/>
    <geom type="mesh" mesh="R19" xyaxes="1 0 0 0 0 1" pos="0 0 0"/>
    <geom type="mesh" mesh="L19" xyaxes="1 0 0 0 0 1" pos="0 0 0"/>
    <geom type="mesh" mesh="R20" xyaxes="1 0 0 0 0 1" pos="0 0 0"/>
    <geom type="mesh" mesh="L20" xyaxes="1 0 0 0 0 1" pos="0 0 0"/>
    <geom type="mesh" mesh="R21" xyaxes="1 0 0 0 0 1" pos="0 0 0"/>
    <geom type="mesh" mesh="L21" xyaxes="1 0 0 0 0 1" pos="0 0 0"/>
    <geom type="mesh" mesh="R22" xyaxes="1 0 0 0 0 1" pos="0 0 0"/>
    <geom type="mesh" mesh="L22" xyaxes="1 0 0 0 0 1" pos="0 0 0"/>


    <body name="chassis" pos="0 0 0.5">
      <geom name="chassis_geom" type="box" size="0.3 0.15 0.05" rgba="0.3 0.3 0.3 1" mass="100" contype="1" conaffinity="1"/>
      <joint name="chassis_free" type="free"/>

      <site name="ray_site_front" pos="0.3 0 0.1" quat="0.7071 0 -0.7071 0" type="sphere" size="0.05"/>
      <site name="ray_site_right1" pos="0.125 0.17 0.1" quat="0.7071 0.7071 0 0" type="sphere" size="0.05"/>
      <site name="ray_site_right2" pos="-0.125 0.17 0.1" quat="0.7071 0.7071 0 0" type="sphere" size="0.05"/>
      <site name="ray_site_back" pos="-0.3 0 0.1" quat="0 -0.7071 0 -0.7071" type="sphere" size="0.05"/>
      <site name="ray_site_left1" pos="0.125 -0.17 0.1" quat="0.7071 -0.7071 0 0" type="sphere" size="0.05"/>
      <site name="ray_site_left2" pos="-0.125 -0.17 0.1" quat="0.7071 -0.7071 0 0" type="sphere" size="0.05"/>
      <site name="imu_site" pos="0 0 0.1" size="0.05" rgba="0 1 0 1"/>

      <body name="rear_left" pos="0.3 -0.25 0" euler="90 0 0">
        <joint name="rear_left_axle" type="hinge" axis="0 0 1" limited="false"/>
        <geom name="rear_left_wheel" type="cylinder" size="0.08 0.04" rgba="0.7 0.7 0.7 1" mass="20" contype="1" conaffinity="1"/>
      </body>

      <body name="rear_right" pos="0.3 0.25 0" euler="90 0 0">
        <joint name="rear_right_axle" type="hinge" axis="0 0 1" limited="false"/>
        <geom name="rear_right_wheel" type="cylinder" size="0.08 0.04" rgba="0.7 0.7 0.7 1" mass="20" contype="1" conaffinity="1"/>
      </body>

      <body name="front_left_mount" pos="-0.3 -0.25 0" euler="0 90 0">
        <inertial pos="0 0 0" mass="0.001" diaginertia="0.001 0.001 0.001"/>
        <joint name="front_left_steer" type="hinge" axis="1 0 0" limited="true" range="-20 20"/>
        <body name="front_left" pos="0 0 0" euler="90 0 0">
          <joint name="front_left_axle" type="hinge" axis="0 0 1" limited="false"/>
          <geom name="front_left_wheel" type="cylinder" size="0.08 0.04" rgba="0.7 0.7 0.7 1" mass="20" friction="0.1 0.1 0.1" condim="1" contype="1" conaffinity="1"/>
        </body>
      </body>

      <body name="front_right_mount" pos="-0.3 0.25 0" euler="0 90 0">
        <inertial pos="0 0 0" mass="0.001" diaginertia="0.001 0.001 0.001"/>
        <joint name="front_right_steer" type="hinge" axis="1 0 0" limited="true" range="-20 20"/>
        <body name="front_right" pos="0 0 0" euler="90 0 0">
          <joint name="front_right_axle" type="hinge" axis="0 0 1" limited="false"/>
          <geom name="front_right_wheel" type="cylinder" size="0.08 0.04" rgba="0.7 0.7 0.7 1" mass="20" friction="0.1 0.1 0.1" condim="1" contype="1" conaffinity="1"/>
        </body>
      </body>
    </body>
  </worldbody>

  <tendon>
      <fixed name="rear_axles">
        <joint joint="rear_left_axle" coef="1"/>
        <joint joint="rear_right_axle" coef="1"/>
      </fixed>

      <fixed name="front_steer">
        <joint joint="front_left_steer" coef="1"/>
        <joint joint="front_right_steer" coef="1"/>
      </fixed>
   </tendon>

  <actuator>
    <motor name="rear_drive" tendon="rear_axles" gear="25" ctrlrange="0 1"/>
    <position name="front_steer_ctrl" tendon="front_steer" kp="100" ctrlrange="-1 1"/>
  </actuator>

  <sensor>
    <rangefinder name="lidar_front" site="ray_site_front" cutoff="5"/>
    <rangefinder name="lidar_right1" site="ray_site_right1" cutoff="5"/>
    <rangefinder name="lidar_right2" site="ray_site_right2" cutoff="5"/>
    <rangefinder name="lidar_back" site="ray_site_back" cutoff="5"/>
    <rangefinder name="lidar_left1" site="ray_site_left1" cutoff="5"/>
    <rangefinder name="lidar_left2" site="ray_site_left2" cutoff="5"/>
    <velocimeter name="imu_velocity" site="imu_site"/>
    <accelerometer name="imu_acceleration" site="imu_site"/>
  </sensor>
</mujoco>