<mujoco model="TurboV1">

  <compiler meshdir="/Users/venky/Documents/Projects/DRL_TurboEngine/DRLTurboEngines/DRL_TurboEngine_V2/Tracks_STL/Track_V2"/>
  <compiler angle="degree" coordinate="local"/>
  <option timestep="0.01"/>

  <default>
    <joint armature="0.01" damping="1" limited="true"/>
  </default>

  <asset>
  <mesh name="T2" file="2.stl" scale="0.05 0.05 0.05"/>
  <mesh name="T3" file="3.stl" scale="0.05 0.05 0.05"/>
  <mesh name="T4" file="4.stl" scale="0.05 0.05 0.05"/>
  <mesh name="T5" file="5.stl" scale="0.05 0.05 0.05"/>
  <mesh name="T6" file="6.stl" scale="0.05 0.05 0.05"/>
  <mesh name="T7" file="7.stl" scale="0.05 0.05 0.05"/>
  <mesh name="T8" file="8.stl" scale="0.05 0.05 0.05"/>
  <mesh name="T9" file="9.stl" scale="0.05 0.05 0.05"/>
  <mesh name="T10" file="10.stl" scale="0.05 0.05 0.05"/>
  <mesh name="T11" file="11.stl" scale="0.05 0.05 0.05"/>
  <mesh name="T12" file="12.stl" scale="0.05 0.05 0.05"/>
  <mesh name="T13" file="13.stl" scale="0.05 0.05 0.05"/>
  <mesh name="T14" file="14.stl" scale="0.05 0.05 0.05"/>
  <mesh name="T15" file="15.stl" scale="0.05 0.05 0.05"/>
  <mesh name="T16" file="16.stl" scale="0.05 0.05 0.05"/>
  <mesh name="T17" file="17.stl" scale="0.05 0.05 0.05"/>
  <mesh name="T18" file="18.stl" scale="0.05 0.05 0.05"/>
  <mesh name="T19" file="19.stl" scale="0.05 0.05 0.05"/>
  <mesh name="T20" file="20.stl" scale="0.05 0.05 0.05"/>
  <mesh name="T21" file="21.stl" scale="0.05 0.05 0.05"/>
  <mesh name="T22" file="22.stl" scale="0.05 0.05 0.05"/>
  <mesh name="T23" file="23.stl" scale="0.05 0.05 0.05"/>
  <mesh name="T24" file="24.stl" scale="0.05 0.05 0.05"/>
  <mesh name="T29" file="29.stl" scale="0.05 0.05 0.05"/>
  <mesh name="T30" file="30.stl" scale="0.05 0.05 0.05"/>
  <mesh name="T31" file="31.stl" scale="0.05 0.05 0.05"/>
  <mesh name="T32" file="32.stl" scale="0.05 0.05 0.05"/>
  <mesh name="T33" file="33.stl" scale="0.05 0.05 0.05"/>
  <mesh name="T34" file="34.stl" scale="0.05 0.05 0.05"/>
  <mesh name="T35" file="35.stl" scale="0.05 0.05 0.05"/>
  <mesh name="T36" file="36.stl" scale="0.05 0.05 0.05"/>
  <mesh name="T37" file="37.stl" scale="0.05 0.05 0.05"/>
  <mesh name="T38" file="38.stl" scale="0.05 0.05 0.05"/>
  <mesh name="T39" file="39.stl" scale="0.05 0.05 0.05"/>
  <mesh name="T40" file="40.stl" scale="0.05 0.05 0.05"/>
  <mesh name="T41" file="41.stl" scale="0.05 0.05 0.05"/>
  <mesh name="T42" file="42.stl" scale="0.05 0.05 0.05"/>
  <mesh name="T43" file="43.stl" scale="0.05 0.05 0.05"/>
  <mesh name="T44" file="44.stl" scale="0.05 0.05 0.05"/>
  <mesh name="T45" file="45.stl" scale="0.05 0.05 0.05"/>
  <mesh name="T46" file="46.stl" scale="0.05 0.05 0.05"/>
  <mesh name="T47" file="47.stl" scale="0.05 0.05 0.05"/>
  <mesh name="T48" file="48.stl" scale="0.05 0.05 0.05"/>
  <mesh name="T50" file="50.stl" scale="0.05 0.05 0.05"/>
  <mesh name="T51" file="51.stl" scale="0.05 0.05 0.05"/>
</asset>


  <worldbody>
    <geom name="ground Plane" type="plane" pos="0 0 0" size="50 50 1" rgba="1 1 1 1"/> 
<geom name="wall_boundary1" type="box" pos="50 0 5" size="0.5 50 5" rgba="0.7 0.7 0.7 1" contype="1" conaffinity="1"/>
<geom name="wall_boundary2" type="box" pos="-50 0 5" size="0.5 50 5" rgba="0.7 0.7 0.7 1" contype="1" conaffinity="1"/>
<geom name="wall_boundary3" type="box" pos="0 -50 5" size="50 0.5 5" rgba="0.7 0.7 0.7 1" contype="1" conaffinity="1"/>
<geom name="wall_boundary4" type="box" pos="0 50 5" size="50 0.5 5" rgba="0.7 0.7 0.7 1" contype="1" conaffinity="1"/>


<geom type="mesh" mesh="T2" xyaxes="1 0 0 0 0 1" pos="0 0 0.5"/>
<geom type="mesh" mesh="T3" xyaxes="1 0 0 0 0 1" pos="0 0 0.5"/>
<geom type="mesh" mesh="T4" xyaxes="1 0 0 0 0 1" pos="0 0 0.5"/>
<geom type="mesh" mesh="T5" xyaxes="1 0 0 0 0 1" pos="0 0 0.5"/>
<geom type="mesh" mesh="T6" xyaxes="1 0 0 0 0 1" pos="0 0 0.5"/>
<geom type="mesh" mesh="T7" xyaxes="1 0 0 0 0 1" pos="0 0 0.5"/>
<geom type="mesh" mesh="T8" xyaxes="1 0 0 0 0 1" pos="0 0 0.5"/>
<geom type="mesh" mesh="T9" xyaxes="1 0 0 0 0 1" pos="0 0 0.5"/>
<geom type="mesh" mesh="T10" xyaxes="1 0 0 0 0 1" pos="0 0 0.5"/>
<geom type="mesh" mesh="T11" xyaxes="1 0 0 0 0 1" pos="0 0 0.5"/>
<geom type="mesh" mesh="T12" xyaxes="1 0 0 0 0 1" pos="0 0 0.5"/>
<geom type="mesh" mesh="T13" xyaxes="1 0 0 0 0 1" pos="0 0 0.5"/>
<geom type="mesh" mesh="T14" xyaxes="1 0 0 0 0 1" pos="0 0 0.5"/>
<geom type="mesh" mesh="T15" xyaxes="1 0 0 0 0 1" pos="0 0 0.5"/>
<geom type="mesh" mesh="T16" xyaxes="1 0 0 0 0 1" pos="0 0 0.5"/>
<geom type="mesh" mesh="T17" xyaxes="1 0 0 0 0 1" pos="0 0 0.5"/>
<geom type="mesh" mesh="T18" xyaxes="1 0 0 0 0 1" pos="0 0 0.5"/>
<geom type="mesh" mesh="T19" xyaxes="1 0 0 0 0 1" pos="0 0 0.5"/>
<geom type="mesh" mesh="T20" xyaxes="1 0 0 0 0 1" pos="0 0 0.5"/>
<geom type="mesh" mesh="T21" xyaxes="1 0 0 0 0 1" pos="0 0 0.5"/>
<geom type="mesh" mesh="T22" xyaxes="1 0 0 0 0 1" pos="0 0 0.5"/>
<geom type="mesh" mesh="T23" xyaxes="1 0 0 0 0 1" pos="0 0 0.5"/>
<geom type="mesh" mesh="T24" xyaxes="1 0 0 0 0 1" pos="0 0 0.5"/>
<geom type="mesh" mesh="T29" xyaxes="1 0 0 0 0 1" pos="0 0 0.5"/>
<geom type="mesh" mesh="T30" xyaxes="1 0 0 0 0 1" pos="0 0 0.5"/>
<geom type="mesh" mesh="T31" xyaxes="1 0 0 0 0 1" pos="0 0 0.5"/>
<geom type="mesh" mesh="T32" xyaxes="1 0 0 0 0 1" pos="0 0 0.5"/>
<geom type="mesh" mesh="T33" xyaxes="1 0 0 0 0 1" pos="0 0 0.5"/>
<geom type="mesh" mesh="T34" xyaxes="1 0 0 0 0 1" pos="0 0 0.5"/>
<geom type="mesh" mesh="T35" xyaxes="1 0 0 0 0 1" pos="0 0 0.5"/>
<geom type="mesh" mesh="T36" xyaxes="1 0 0 0 0 1" pos="0 0 0.5"/>
<geom type="mesh" mesh="T37" xyaxes="1 0 0 0 0 1" pos="0 0 0.5"/>
<geom type="mesh" mesh="T38" xyaxes="1 0 0 0 0 1" pos="0 0 0.5"/>
<geom type="mesh" mesh="T39" xyaxes="1 0 0 0 0 1" pos="0 0 0.5"/>
<geom type="mesh" mesh="T40" xyaxes="1 0 0 0 0 1" pos="0 0 0.5"/>
<geom type="mesh" mesh="T41" xyaxes="1 0 0 0 0 1" pos="0 0 0.5"/>
<geom type="mesh" mesh="T42" xyaxes="1 0 0 0 0 1" pos="0 0 0.5"/>
<geom type="mesh" mesh="T43" xyaxes="1 0 0 0 0 1" pos="0 0 0.5"/>
<geom type="mesh" mesh="T44" xyaxes="1 0 0 0 0 1" pos="0 0 0.5"/>
<geom type="mesh" mesh="T45" xyaxes="1 0 0 0 0 1" pos="0 0 0.5"/>
<geom type="mesh" mesh="T46" xyaxes="1 0 0 0 0 1" pos="0 0 0.5"/>
<geom type="mesh" mesh="T47" xyaxes="1 0 0 0 0 1" pos="0 0 0.5"/>
<geom type="mesh" mesh="T48" xyaxes="1 0 0 0 0 1" pos="0 0 0.5"/>
<geom type="mesh" mesh="T50" xyaxes="1 0 0 0 0 1" pos="0 0 0.5"/>
<geom type="mesh" mesh="T51" xyaxes="1 0 0 0 0 1" pos="0 0 0.5"/>




    <body name="chassis" pos="25 -30 0.5" euler="0 0 -90">
      <geom name="chassis_geom" type="box" size="0.3 0.15 0.05" rgba="0.3 0.3 0.3 1" mass="100" contype="1" conaffinity="1"/>
      <joint name="chassis_free" type="free"/>

      <site name="ray_site_front" pos="0.3 0 0.1" quat="0.7071 0 -0.7071 0" type="sphere" size="0.05"/>
      <site name="ray_site_right1" pos="0.125 0.17 0.1" quat="0.7071 0.7071 0 0" type="sphere" size="0.05"/>
      <site name="ray_site_right2" pos="-0.125 0.17 0.1" quat="0.7071 0.7071 0 0" type="sphere" size="0.05"/>
      <site name="ray_site_back" pos="-0.3 0 0.1" quat="0 -0.7071 0 -0.7071" type="sphere" size="0.05"/>
      <site name="ray_site_left1" pos="0.125 -0.17 0.1" quat="0.7071 -0.7071 0 0" type="sphere" size="0.05"/>
      <site name="ray_site_left2" pos="-0.125 -0.17 0.1" quat="0.7071 -0.7071 0 0" type="sphere" size="0.05"/>
      <site name="imu_site" pos="0 0 0.1" size="0.05" rgba="0 1 0 1"/>

      <body name="rear_left" pos="0.3 -0.25 0" euler="90 0 0">
        <joint name="rear_left_axle" type="hinge" axis="0 0 1" limited="false"/>
        <geom name="rear_left_wheel" type="cylinder" size="0.08 0.04" rgba="0.7 0.7 0.7 1" mass="20" contype="1" conaffinity="1"/>
      </body>

      <body name="rear_right" pos="0.3 0.25 0" euler="90 0 0">
        <joint name="rear_right_axle" type="hinge" axis="0 0 1" limited="false"/>
        <geom name="rear_right_wheel" type="cylinder" size="0.08 0.04" rgba="0.7 0.7 0.7 1" mass="20" contype="1" conaffinity="1"/>
      </body>

      <body name="front_left_mount" pos="-0.3 -0.25 0" euler="0 90 0">
        <inertial pos="0 0 0" mass="0.001" diaginertia="0.001 0.001 0.001"/>
        <joint name="front_left_steer" type="hinge" axis="1 0 0" limited="true" range="-20 20"/>
        <body name="front_left" pos="0 0 0" euler="90 0 0">
          <joint name="front_left_axle" type="hinge" axis="0 0 1" limited="false"/>
          <geom name="front_left_wheel" type="cylinder" size="0.08 0.04" rgba="0.7 0.7 0.7 1" mass="20" friction="0.1 0.1 0.1" condim="1" contype="1" conaffinity="1"/>
        </body>
      </body>

      <body name="front_right_mount" pos="-0.3 0.25 0" euler="0 90 0">
        <inertial pos="0 0 0" mass="0.001" diaginertia="0.001 0.001 0.001"/>
        <joint name="front_right_steer" type="hinge" axis="1 0 0" limited="true" range="-20 20"/>
        <body name="front_right" pos="0 0 0" euler="90 0 0">
          <joint name="front_right_axle" type="hinge" axis="0 0 1" limited="false"/>
          <geom name="front_right_wheel" type="cylinder" size="0.08 0.04" rgba="0.7 0.7 0.7 1" mass="20" friction="0.1 0.1 0.1" condim="1" contype="1" conaffinity="1"/>
        </body>
      </body>
    </body>
  </worldbody>

  <tendon>
      <fixed name="rear_axles">
        <joint joint="rear_left_axle" coef="1"/>
        <joint joint="rear_right_axle" coef="1"/>
      </fixed>

      <fixed name="front_steer">
        <joint joint="front_left_steer" coef="1"/>
        <joint joint="front_right_steer" coef="1"/>
      </fixed>
   </tendon>

  <actuator>
    <motor name="rear_drive" tendon="rear_axles" gear="25" ctrlrange="0 1"/>
    <position name="front_steer_ctrl" tendon="front_steer" kp="100" ctrlrange="-1 1"/>
  </actuator>

  <sensor>
    <rangefinder name="lidar_front" site="ray_site_front" cutoff="5"/>
    <rangefinder name="lidar_right1" site="ray_site_right1" cutoff="5"/>
    <rangefinder name="lidar_right2" site="ray_site_right2" cutoff="5"/>
    <rangefinder name="lidar_back" site="ray_site_back" cutoff="5"/>
    <rangefinder name="lidar_left1" site="ray_site_left1" cutoff="5"/>
    <rangefinder name="lidar_left2" site="ray_site_left2" cutoff="5"/>
    <velocimeter name="imu_velocity" site="imu_site"/>
    <accelerometer name="imu_acceleration" site="imu_site"/>
  </sensor>
</mujoco>